2025-02-02 11:28:52,719 - INFO - Mila startup
2025-02-02 11:29:34,883 - INFO - Mila startup
2025-02-02 11:29:34,891 - ERROR - Erro na operação do banco de dados: You can only execute one statement at a time.
2025-02-02 11:30:07,102 - INFO - Mila startup
2025-02-02 11:30:07,236 - INFO - [31m[1mWARNING: This is a development server. Do not use it in a production deployment. Use a production WSGI server instead.[0m
 * Running on http://127.0.0.1:5000
2025-02-02 11:30:07,237 - INFO - [33mPress CTRL+C to quit[0m
2025-02-02 11:30:41,846 - ERROR - Exception on / [GET]
Traceback (most recent call last):
  File "C:\projetos\Mila_IA\venv\Lib\site-packages\flask\app.py", line 2190, in wsgi_app
    response = self.full_dispatch_request()
  File "C:\projetos\Mila_IA\venv\Lib\site-packages\flask\app.py", line 1486, in full_dispatch_request
    rv = self.handle_user_exception(e)
  File "C:\projetos\Mila_IA\venv\Lib\site-packages\flask\app.py", line 1484, in full_dispatch_request
    rv = self.dispatch_request()
  File "C:\projetos\Mila_IA\venv\Lib\site-packages\flask\app.py", line 1469, in dispatch_request
    return self.ensure_sync(self.view_functions[rule.endpoint])(**view_args)
           ~~~~~~~~~~~~~~~~~~~~~~~~~~~~~~~~~~~~~~~~~~~~~~~~~~~~^^^^^^^^^^^^^
  File "C:\projetos\Mila_IA\app_new.py", line 189, in index
    return render_template('index.html')
  File "C:\projetos\Mila_IA\venv\Lib\site-packages\flask\templating.py", line 150, in render_template
    template = app.jinja_env.get_or_select_template(template_name_or_list)
  File "C:\projetos\Mila_IA\venv\Lib\site-packages\jinja2\environment.py", line 1087, in get_or_select_template
    return self.get_template(template_name_or_list, parent, globals)
           ~~~~~~~~~~~~~~~~~^^^^^^^^^^^^^^^^^^^^^^^^^^^^^^^^^^^^^^^^
  File "C:\projetos\Mila_IA\venv\Lib\site-packages\jinja2\environment.py", line 1016, in get_template
    return self._load_template(name, globals)
           ~~~~~~~~~~~~~~~~~~~^^^^^^^^^^^^^^^
  File "C:\projetos\Mila_IA\venv\Lib\site-packages\jinja2\environment.py", line 975, in _load_template
    template = self.loader.load(self, name, self.make_globals(globals))
  File "C:\projetos\Mila_IA\venv\Lib\site-packages\jinja2\loaders.py", line 126, in load
    source, filename, uptodate = self.get_source(environment, name)
                                 ~~~~~~~~~~~~~~~^^^^^^^^^^^^^^^^^^^
  File "C:\projetos\Mila_IA\venv\Lib\site-packages\flask\templating.py", line 64, in get_source
    return self._get_source_fast(environment, template)
           ~~~~~~~~~~~~~~~~~~~~~^^^^^^^^^^^^^^^^^^^^^^^
  File "C:\projetos\Mila_IA\venv\Lib\site-packages\flask\templating.py", line 98, in _get_source_fast
    raise TemplateNotFound(template)
jinja2.exceptions.TemplateNotFound: index.html
2025-02-02 11:30:41,870 - INFO - 127.0.0.1 - - [02/Feb/2025 11:30:41] "[35m[1mGET / HTTP/1.1[0m" 500 -
2025-02-02 11:30:57,029 - ERROR - Exception on /login [GET]
Traceback (most recent call last):
  File "C:\projetos\Mila_IA\venv\Lib\site-packages\flask\app.py", line 2190, in wsgi_app
    response = self.full_dispatch_request()
  File "C:\projetos\Mila_IA\venv\Lib\site-packages\flask\app.py", line 1486, in full_dispatch_request
    rv = self.handle_user_exception(e)
  File "C:\projetos\Mila_IA\venv\Lib\site-packages\flask\app.py", line 1484, in full_dispatch_request
    rv = self.dispatch_request()
  File "C:\projetos\Mila_IA\venv\Lib\site-packages\flask\app.py", line 1469, in dispatch_request
    return self.ensure_sync(self.view_functions[rule.endpoint])(**view_args)
           ~~~~~~~~~~~~~~~~~~~~~~~~~~~~~~~~~~~~~~~~~~~~~~~~~~~~^^^^^^^^^^^^^
  File "C:\projetos\Mila_IA\auth.py", line 72, in login
    return render_template('login.html')
  File "C:\projetos\Mila_IA\venv\Lib\site-packages\flask\templating.py", line 151, in render_template
    return _render(app, template, context)
  File "C:\projetos\Mila_IA\venv\Lib\site-packages\flask\templating.py", line 132, in _render
    rv = template.render(context)
  File "C:\projetos\Mila_IA\venv\Lib\site-packages\jinja2\environment.py", line 1295, in render
    self.environment.handle_exception()
    ~~~~~~~~~~~~~~~~~~~~~~~~~~~~~~~~~^^
  File "C:\projetos\Mila_IA\venv\Lib\site-packages\jinja2\environment.py", line 942, in handle_exception
    raise rewrite_traceback_stack(source=source)
  File "C:\projetos\Mila_IA\templates\login.html", line 38, in top-level template code
    <a href="{{ url_for('recuperar_senha') }}">Esqueceu sua senha?</a>
    ^^^^^^^^^
  File "C:\projetos\Mila_IA\venv\Lib\site-packages\flask\app.py", line 1697, in url_for
    return self.handle_url_build_error(error, endpoint, values)
           ~~~~~~~~~~~~~~~~~~~~~~~~~~~^^^^^^^^^^^^^^^^^^^^^^^^^
  File "C:\projetos\Mila_IA\venv\Lib\site-packages\flask\app.py", line 1686, in url_for
    rv = url_adapter.build(  # type: ignore[union-attr]
        endpoint,
    ...<3 lines>...
        force_external=_external,
    )
  File "C:\projetos\Mila_IA\venv\Lib\site-packages\werkzeug\routing\map.py", line 950, in build
    raise BuildError(endpoint, values, method, self)
werkzeug.routing.exceptions.BuildError: Could not build url for endpoint 'recuperar_senha'. Did you mean 'auth.alterar_senha' instead?
2025-02-02 11:30:57,041 - INFO - 127.0.0.1 - - [02/Feb/2025 11:30:57] "[35m[1mGET /login HTTP/1.1[0m" 500 -
2025-02-02 11:32:10,975 - ERROR - Exception on / [GET]
Traceback (most recent call last):
  File "C:\projetos\Mila_IA\venv\Lib\site-packages\flask\app.py", line 2190, in wsgi_app
    response = self.full_dispatch_request()
  File "C:\projetos\Mila_IA\venv\Lib\site-packages\flask\app.py", line 1486, in full_dispatch_request
    rv = self.handle_user_exception(e)
  File "C:\projetos\Mila_IA\venv\Lib\site-packages\flask\app.py", line 1484, in full_dispatch_request
    rv = self.dispatch_request()
  File "C:\projetos\Mila_IA\venv\Lib\site-packages\flask\app.py", line 1469, in dispatch_request
    return self.ensure_sync(self.view_functions[rule.endpoint])(**view_args)
           ~~~~~~~~~~~~~~~~~~~~~~~~~~~~~~~~~~~~~~~~~~~~~~~~~~~~^^^^^^^^^^^^^
  File "C:\projetos\Mila_IA\app_new.py", line 189, in index
    return render_template('index.html')
  File "C:\projetos\Mila_IA\venv\Lib\site-packages\flask\templating.py", line 150, in render_template
    template = app.jinja_env.get_or_select_template(template_name_or_list)
  File "C:\projetos\Mila_IA\venv\Lib\site-packages\jinja2\environment.py", line 1087, in get_or_select_template
    return self.get_template(template_name_or_list, parent, globals)
           ~~~~~~~~~~~~~~~~~^^^^^^^^^^^^^^^^^^^^^^^^^^^^^^^^^^^^^^^^
  File "C:\projetos\Mila_IA\venv\Lib\site-packages\jinja2\environment.py", line 1016, in get_template
    return self._load_template(name, globals)
           ~~~~~~~~~~~~~~~~~~~^^^^^^^^^^^^^^^
  File "C:\projetos\Mila_IA\venv\Lib\site-packages\jinja2\environment.py", line 975, in _load_template
    template = self.loader.load(self, name, self.make_globals(globals))
  File "C:\projetos\Mila_IA\venv\Lib\site-packages\jinja2\loaders.py", line 126, in load
    source, filename, uptodate = self.get_source(environment, name)
                                 ~~~~~~~~~~~~~~~^^^^^^^^^^^^^^^^^^^
  File "C:\projetos\Mila_IA\venv\Lib\site-packages\flask\templating.py", line 64, in get_source
    return self._get_source_fast(environment, template)
           ~~~~~~~~~~~~~~~~~~~~~^^^^^^^^^^^^^^^^^^^^^^^
  File "C:\projetos\Mila_IA\venv\Lib\site-packages\flask\templating.py", line 98, in _get_source_fast
    raise TemplateNotFound(template)
jinja2.exceptions.TemplateNotFound: index.html
2025-02-02 11:32:10,982 - INFO - 127.0.0.1 - - [02/Feb/2025 11:32:10] "[35m[1mGET / HTTP/1.1[0m" 500 -
2025-02-02 11:32:36,603 - INFO - [31m[1mWARNING: This is a development server. Do not use it in a production deployment. Use a production WSGI server instead.[0m
 * Running on http://127.0.0.1:5000
2025-02-02 11:32:36,604 - INFO - [33mPress CTRL+C to quit[0m
2025-02-02 11:32:36,613 - INFO -  * Restarting with stat
2025-02-02 11:32:38,031 - WARNING -  * Debugger is active!
2025-02-02 11:32:38,060 - INFO -  * Debugger PIN: 161-353-765
2025-02-02 11:33:14,773 - INFO -  * Detected change in 'C:\\projetos\\Mila_IA\\app_new.py', reloading
2025-02-02 11:33:14,975 - INFO -  * Restarting with stat
2025-02-02 11:33:16,818 - WARNING -  * Debugger is active!
2025-02-02 11:33:16,857 - INFO -  * Debugger PIN: 161-353-765
2025-02-02 11:33:46,169 - INFO -  * Detected change in 'C:\\projetos\\Mila_IA\\app_new.py', reloading
2025-02-02 11:33:46,827 - INFO -  * Restarting with stat
2025-02-02 11:33:48,368 - WARNING -  * Debugger is active!
2025-02-02 11:33:48,395 - INFO -  * Debugger PIN: 161-353-765
2025-02-02 11:34:03,783 - INFO - [31m[1mWARNING: This is a development server. Do not use it in a production deployment. Use a production WSGI server instead.[0m
 * Running on http://127.0.0.1:5000
2025-02-02 11:34:03,783 - INFO - [33mPress CTRL+C to quit[0m
2025-02-02 11:34:03,800 - INFO -  * Restarting with stat
2025-02-02 11:34:05,581 - WARNING -  * Debugger is active!
2025-02-02 11:34:05,610 - INFO -  * Debugger PIN: 161-353-765
2025-02-02 11:34:52,620 - INFO - 127.0.0.1 - - [02/Feb/2025 11:34:52] "GET / HTTP/1.1" 200 -
2025-02-02 11:34:52,931 - INFO - 127.0.0.1 - - [02/Feb/2025 11:34:52] "GET /static/css/security.css HTTP/1.1" 200 -
2025-02-02 11:34:52,957 - INFO - 127.0.0.1 - - [02/Feb/2025 11:34:52] "[36mGET /static/css/custom.css HTTP/1.1[0m" 304 -
2025-02-02 11:34:57,030 - ERROR - Exception on /login [GET]
Traceback (most recent call last):
  File "C:\projetos\Mila_IA\venv\Lib\site-packages\flask\app.py", line 2190, in wsgi_app
    response = self.full_dispatch_request()
  File "C:\projetos\Mila_IA\venv\Lib\site-packages\flask\app.py", line 1486, in full_dispatch_request
    rv = self.handle_user_exception(e)
  File "C:\projetos\Mila_IA\venv\Lib\site-packages\flask\app.py", line 1484, in full_dispatch_request
    rv = self.dispatch_request()
  File "C:\projetos\Mila_IA\venv\Lib\site-packages\flask\app.py", line 1469, in dispatch_request
    return self.ensure_sync(self.view_functions[rule.endpoint])(**view_args)
           ~~~~~~~~~~~~~~~~~~~~~~~~~~~~~~~~~~~~~~~~~~~~~~~~~~~~^^^^^^^^^^^^^
  File "C:\projetos\Mila_IA\auth.py", line 72, in login
    return render_template('login.html')
  File "C:\projetos\Mila_IA\venv\Lib\site-packages\flask\templating.py", line 151, in render_template
    return _render(app, template, context)
  File "C:\projetos\Mila_IA\venv\Lib\site-packages\flask\templating.py", line 132, in _render
    rv = template.render(context)
  File "C:\projetos\Mila_IA\venv\Lib\site-packages\jinja2\environment.py", line 1295, in render
    self.environment.handle_exception()
    ~~~~~~~~~~~~~~~~~~~~~~~~~~~~~~~~~^^
  File "C:\projetos\Mila_IA\venv\Lib\site-packages\jinja2\environment.py", line 942, in handle_exception
    raise rewrite_traceback_stack(source=source)
  File "C:\projetos\Mila_IA\templates\login.html", line 38, in top-level template code
    <a href="{{ url_for('recuperar_senha') }}">Esqueceu sua senha?</a>
    ^^^^^^^^^
  File "C:\projetos\Mila_IA\venv\Lib\site-packages\flask\app.py", line 1697, in url_for
    return self.handle_url_build_error(error, endpoint, values)
           ~~~~~~~~~~~~~~~~~~~~~~~~~~~^^^^^^^^^^^^^^^^^^^^^^^^^
  File "C:\projetos\Mila_IA\venv\Lib\site-packages\flask\app.py", line 1686, in url_for
    rv = url_adapter.build(  # type: ignore[union-attr]
        endpoint,
    ...<3 lines>...
        force_external=_external,
    )
  File "C:\projetos\Mila_IA\venv\Lib\site-packages\werkzeug\routing\map.py", line 950, in build
    raise BuildError(endpoint, values, method, self)
werkzeug.routing.exceptions.BuildError: Could not build url for endpoint 'recuperar_senha'. Did you mean 'auth.alterar_senha' instead?
2025-02-02 11:34:57,039 - INFO - 127.0.0.1 - - [02/Feb/2025 11:34:57] "[35m[1mGET /login HTTP/1.1[0m" 500 -
2025-02-02 11:35:00,915 - ERROR - Exception on /login [GET]
Traceback (most recent call last):
  File "C:\projetos\Mila_IA\venv\Lib\site-packages\flask\app.py", line 2190, in wsgi_app
    response = self.full_dispatch_request()
  File "C:\projetos\Mila_IA\venv\Lib\site-packages\flask\app.py", line 1486, in full_dispatch_request
    rv = self.handle_user_exception(e)
  File "C:\projetos\Mila_IA\venv\Lib\site-packages\flask\app.py", line 1484, in full_dispatch_request
    rv = self.dispatch_request()
  File "C:\projetos\Mila_IA\venv\Lib\site-packages\flask\app.py", line 1469, in dispatch_request
    return self.ensure_sync(self.view_functions[rule.endpoint])(**view_args)
           ~~~~~~~~~~~~~~~~~~~~~~~~~~~~~~~~~~~~~~~~~~~~~~~~~~~~^^^^^^^^^^^^^
  File "C:\projetos\Mila_IA\auth.py", line 72, in login
    return render_template('login.html')
  File "C:\projetos\Mila_IA\venv\Lib\site-packages\flask\templating.py", line 151, in render_template
    return _render(app, template, context)
  File "C:\projetos\Mila_IA\venv\Lib\site-packages\flask\templating.py", line 132, in _render
    rv = template.render(context)
  File "C:\projetos\Mila_IA\venv\Lib\site-packages\jinja2\environment.py", line 1295, in render
    self.environment.handle_exception()
    ~~~~~~~~~~~~~~~~~~~~~~~~~~~~~~~~~^^
  File "C:\projetos\Mila_IA\venv\Lib\site-packages\jinja2\environment.py", line 942, in handle_exception
    raise rewrite_traceback_stack(source=source)
  File "C:\projetos\Mila_IA\templates\login.html", line 38, in top-level template code
    <a href="{{ url_for('recuperar_senha') }}">Esqueceu sua senha?</a>
    ^^^^^^^^^
  File "C:\projetos\Mila_IA\venv\Lib\site-packages\flask\app.py", line 1697, in url_for
    return self.handle_url_build_error(error, endpoint, values)
           ~~~~~~~~~~~~~~~~~~~~~~~~~~~^^^^^^^^^^^^^^^^^^^^^^^^^
  File "C:\projetos\Mila_IA\venv\Lib\site-packages\flask\app.py", line 1686, in url_for
    rv = url_adapter.build(  # type: ignore[union-attr]
        endpoint,
    ...<3 lines>...
        force_external=_external,
    )
  File "C:\projetos\Mila_IA\venv\Lib\site-packages\werkzeug\routing\map.py", line 950, in build
    raise BuildError(endpoint, values, method, self)
werkzeug.routing.exceptions.BuildError: Could not build url for endpoint 'recuperar_senha'. Did you mean 'auth.alterar_senha' instead?
2025-02-02 11:35:00,928 - INFO - 127.0.0.1 - - [02/Feb/2025 11:35:00] "[35m[1mGET /login HTTP/1.1[0m" 500 -
2025-02-02 11:35:34,588 - INFO -  * Detected change in 'C:\\projetos\\Mila_IA\\auth.py', reloading
2025-02-02 11:35:34,685 - INFO -  * Detected change in 'C:\\projetos\\Mila_IA\\auth.py', reloading
2025-02-02 11:35:35,030 - INFO -  * Restarting with stat
2025-02-02 11:35:35,119 - INFO -  * Restarting with stat
2025-02-02 11:35:37,586 - WARNING -  * Debugger is active!
2025-02-02 11:35:37,587 - WARNING -  * Debugger is active!
2025-02-02 11:35:37,620 - INFO -  * Debugger PIN: 161-353-765
2025-02-02 11:35:37,621 - INFO -  * Debugger PIN: 161-353-765
2025-02-02 11:35:56,811 - INFO - [31m[1mWARNING: This is a development server. Do not use it in a production deployment. Use a production WSGI server instead.[0m
 * Running on http://127.0.0.1:5000
2025-02-02 11:35:56,812 - INFO - [33mPress CTRL+C to quit[0m
2025-02-02 11:35:56,830 - INFO -  * Restarting with stat
2025-02-02 11:35:58,804 - WARNING -  * Debugger is active!
2025-02-02 11:35:58,836 - INFO -  * Debugger PIN: 161-353-765
2025-02-02 11:42:00,767 - INFO - 127.0.0.1 - - [02/Feb/2025 11:42:00] "GET / HTTP/1.1" 200 -
2025-02-02 11:42:00,842 - INFO - 127.0.0.1 - - [02/Feb/2025 11:42:00] "[36mGET /static/css/custom.css HTTP/1.1[0m" 304 -
2025-02-02 11:42:00,850 - INFO - 127.0.0.1 - - [02/Feb/2025 11:42:00] "[36mGET /static/css/security.css HTTP/1.1[0m" 304 -
2025-02-02 11:42:02,451 - ERROR - Exception on /login [GET]
Traceback (most recent call last):
  File "C:\projetos\Mila_IA\venv\Lib\site-packages\flask\app.py", line 2190, in wsgi_app
    response = self.full_dispatch_request()
  File "C:\projetos\Mila_IA\venv\Lib\site-packages\flask\app.py", line 1486, in full_dispatch_request
    rv = self.handle_user_exception(e)
  File "C:\projetos\Mila_IA\venv\Lib\site-packages\flask\app.py", line 1484, in full_dispatch_request
    rv = self.dispatch_request()
  File "C:\projetos\Mila_IA\venv\Lib\site-packages\flask\app.py", line 1469, in dispatch_request
    return self.ensure_sync(self.view_functions[rule.endpoint])(**view_args)
           ~~~~~~~~~~~~~~~~~~~~~~~~~~~~~~~~~~~~~~~~~~~~~~~~~~~~^^^^^^^^^^^^^
  File "C:\projetos\Mila_IA\auth.py", line 72, in login
  File "C:\projetos\Mila_IA\venv\Lib\site-packages\flask\templating.py", line 151, in render_template
    return _render(app, template, context)
  File "C:\projetos\Mila_IA\venv\Lib\site-packages\flask\templating.py", line 132, in _render
    rv = template.render(context)
  File "C:\projetos\Mila_IA\venv\Lib\site-packages\jinja2\environment.py", line 1295, in render
    self.environment.handle_exception()
    ~~~~~~~~~~~~~~~~~~~~~~~~~~~~~~~~~^^
  File "C:\projetos\Mila_IA\venv\Lib\site-packages\jinja2\environment.py", line 942, in handle_exception
    raise rewrite_traceback_stack(source=source)
  File "C:\projetos\Mila_IA\templates\login.html", line 38, in top-level template code
    <a href="{{ url_for('recuperar_senha') }}">Esqueceu sua senha?</a>
    ^^^^^^^^^
  File "C:\projetos\Mila_IA\venv\Lib\site-packages\flask\app.py", line 1697, in url_for
    return self.handle_url_build_error(error, endpoint, values)
           ~~~~~~~~~~~~~~~~~~~~~~~~~~~^^^^^^^^^^^^^^^^^^^^^^^^^
  File "C:\projetos\Mila_IA\venv\Lib\site-packages\flask\app.py", line 1686, in url_for
    rv = url_adapter.build(  # type: ignore[union-attr]
        endpoint,
    ...<3 lines>...
        force_external=_external,
    )
  File "C:\projetos\Mila_IA\venv\Lib\site-packages\werkzeug\routing\map.py", line 950, in build
    raise BuildError(endpoint, values, method, self)
werkzeug.routing.exceptions.BuildError: Could not build url for endpoint 'recuperar_senha'. Did you mean 'auth.alterar_senha' instead?
2025-02-02 11:42:02,464 - INFO - 127.0.0.1 - - [02/Feb/2025 11:42:02] "[35m[1mGET /login HTTP/1.1[0m" 500 -
2025-02-02 11:42:07,243 - ERROR - Exception on /login [GET]
Traceback (most recent call last):
  File "C:\projetos\Mila_IA\venv\Lib\site-packages\flask\app.py", line 2190, in wsgi_app
    response = self.full_dispatch_request()
  File "C:\projetos\Mila_IA\venv\Lib\site-packages\flask\app.py", line 1486, in full_dispatch_request
    rv = self.handle_user_exception(e)
  File "C:\projetos\Mila_IA\venv\Lib\site-packages\flask\app.py", line 1484, in full_dispatch_request
    rv = self.dispatch_request()
  File "C:\projetos\Mila_IA\venv\Lib\site-packages\flask\app.py", line 1469, in dispatch_request
    return self.ensure_sync(self.view_functions[rule.endpoint])(**view_args)
           ~~~~~~~~~~~~~~~~~~~~~~~~~~~~~~~~~~~~~~~~~~~~~~~~~~~~^^^^^^^^^^^^^
  File "C:\projetos\Mila_IA\auth.py", line 72, in login
  File "C:\projetos\Mila_IA\venv\Lib\site-packages\flask\templating.py", line 151, in render_template
    return _render(app, template, context)
  File "C:\projetos\Mila_IA\venv\Lib\site-packages\flask\templating.py", line 132, in _render
    rv = template.render(context)
  File "C:\projetos\Mila_IA\venv\Lib\site-packages\jinja2\environment.py", line 1295, in render
    self.environment.handle_exception()
    ~~~~~~~~~~~~~~~~~~~~~~~~~~~~~~~~~^^
  File "C:\projetos\Mila_IA\venv\Lib\site-packages\jinja2\environment.py", line 942, in handle_exception
    raise rewrite_traceback_stack(source=source)
  File "C:\projetos\Mila_IA\templates\login.html", line 38, in top-level template code
    <a href="{{ url_for('recuperar_senha') }}">Esqueceu sua senha?</a>
    ^^^^^^^^^
  File "C:\projetos\Mila_IA\venv\Lib\site-packages\flask\app.py", line 1697, in url_for
    return self.handle_url_build_error(error, endpoint, values)
           ~~~~~~~~~~~~~~~~~~~~~~~~~~~^^^^^^^^^^^^^^^^^^^^^^^^^
  File "C:\projetos\Mila_IA\venv\Lib\site-packages\flask\app.py", line 1686, in url_for
    rv = url_adapter.build(  # type: ignore[union-attr]
        endpoint,
    ...<3 lines>...
        force_external=_external,
    )
  File "C:\projetos\Mila_IA\venv\Lib\site-packages\werkzeug\routing\map.py", line 950, in build
    raise BuildError(endpoint, values, method, self)
werkzeug.routing.exceptions.BuildError: Could not build url for endpoint 'recuperar_senha'. Did you mean 'auth.alterar_senha' instead?
2025-02-02 11:42:07,250 - INFO - 127.0.0.1 - - [02/Feb/2025 11:42:07] "[35m[1mGET /login HTTP/1.1[0m" 500 -
2025-02-02 11:42:18,943 - INFO - 127.0.0.1 - - [02/Feb/2025 11:42:18] "[33mGET /auth/login HTTP/1.1[0m" 404 -
2025-02-02 11:43:33,780 - INFO - [31m[1mWARNING: This is a development server. Do not use it in a production deployment. Use a production WSGI server instead.[0m
 * Running on http://127.0.0.1:5000
2025-02-02 11:43:33,781 - INFO - [33mPress CTRL+C to quit[0m
2025-02-02 11:43:33,800 - INFO -  * Restarting with stat
2025-02-02 11:43:35,790 - WARNING -  * Debugger is active!
2025-02-02 11:43:35,828 - INFO -  * Debugger PIN: 161-353-765
2025-02-02 11:55:17,882 - INFO - 127.0.0.1 - - [02/Feb/2025 11:55:17] "[33mGET /auth/login HTTP/1.1[0m" 404 -
2025-02-02 11:57:05,993 - ERROR - Exception on /login [GET]
Traceback (most recent call last):
  File "C:\projetos\Mila_IA\venv\Lib\site-packages\flask\app.py", line 2190, in wsgi_app
    response = self.full_dispatch_request()
  File "C:\projetos\Mila_IA\venv\Lib\site-packages\flask\app.py", line 1486, in full_dispatch_request
    rv = self.handle_user_exception(e)
  File "C:\projetos\Mila_IA\venv\Lib\site-packages\flask\app.py", line 1484, in full_dispatch_request
    rv = self.dispatch_request()
  File "C:\projetos\Mila_IA\venv\Lib\site-packages\flask\app.py", line 1469, in dispatch_request
    return self.ensure_sync(self.view_functions[rule.endpoint])(**view_args)
           ~~~~~~~~~~~~~~~~~~~~~~~~~~~~~~~~~~~~~~~~~~~~~~~~~~~~^^^^^^^^^^^^^
  File "C:\projetos\Mila_IA\auth.py", line 72, in login
  File "C:\projetos\Mila_IA\venv\Lib\site-packages\flask\templating.py", line 151, in render_template
    return _render(app, template, context)
  File "C:\projetos\Mila_IA\venv\Lib\site-packages\flask\templating.py", line 132, in _render
    rv = template.render(context)
  File "C:\projetos\Mila_IA\venv\Lib\site-packages\jinja2\environment.py", line 1295, in render
    self.environment.handle_exception()
    ~~~~~~~~~~~~~~~~~~~~~~~~~~~~~~~~~^^
  File "C:\projetos\Mila_IA\venv\Lib\site-packages\jinja2\environment.py", line 942, in handle_exception
    raise rewrite_traceback_stack(source=source)
  File "C:\projetos\Mila_IA\templates\login.html", line 38, in top-level template code
    <a href="{{ url_for('recuperar_senha') }}">Esqueceu sua senha?</a>
    ^^^^^^^^^
  File "C:\projetos\Mila_IA\venv\Lib\site-packages\flask\app.py", line 1697, in url_for
    return self.handle_url_build_error(error, endpoint, values)
           ~~~~~~~~~~~~~~~~~~~~~~~~~~~^^^^^^^^^^^^^^^^^^^^^^^^^
  File "C:\projetos\Mila_IA\venv\Lib\site-packages\flask\app.py", line 1686, in url_for
    rv = url_adapter.build(  # type: ignore[union-attr]
        endpoint,
    ...<3 lines>...
        force_external=_external,
    )
  File "C:\projetos\Mila_IA\venv\Lib\site-packages\werkzeug\routing\map.py", line 950, in build
    raise BuildError(endpoint, values, method, self)
werkzeug.routing.exceptions.BuildError: Could not build url for endpoint 'recuperar_senha'. Did you mean 'auth.alterar_senha' instead?
2025-02-02 11:57:06,004 - INFO - 127.0.0.1 - - [02/Feb/2025 11:57:06] "[35m[1mGET /login HTTP/1.1[0m" 500 -
